Workbook

Sheet PRODUCT_MASTER
A1: 사용여부 | B1: 품목코드 | C1: 품목명(규격) | D1: 구분 | E1: 공급단가(ERP) | F1: 제조원가(입력) | G1: 팩/단위 | H1: 비고
A2: Y | B2: 00000001 | C2: 배송비 | D2: 배송비 | E2: 23000 | F2: 23000
A3: Y | B3: 00000002 | C3: 배송비(주말) | D3: 배송비 | E3: 28000 | F3: 28000
A4: Y | B4: A0001 | C4: 유월의보리 볶음소스 | D4: 본사제조 | E4: 41700 | F4: 20181 | G4: 5KG[PAK]
A5: Y | B5: A0002 | C5: 유월의보리 겉절이 소스 | D5: 본사제조 | E5: 36000 | F5: 19973 | G5: 5KG[PAK]
A6: Y | B6: A0003 | C6: 유월의보리 청국장 소스 | D6: 본사제조 | E6: 26800 | F6: 18445 | G6: 5KG[PAK]
A7: Y | B7: A0004 | C7: 유월의보리 간장게장 소스 | D7: 본사제조 | E7: 18000 | F7: 6703 | G7: 5KG[PAK]
A8: Y | B8: A0005 | C8: 유월의보리 비빔고추장 소스 | D8: 본사제조 | E8: 29000 | F8: 15545 | G8: 5KG[PAK]
A9: Y | B9: A0006 | C9: 유월의보리 비빔칼국수 소스 | D9: 본사제조 | E9: 29000 | F9: 13240 | G9: 5KG[PAK]
A10: Y | B10: A0007 | C10: 유월의보리 사골칼국수소스 | D10: 본사제조 | E10: 85756 | F10: 34600 | G10: 5KG[PAK]
A11: Y | B11: A0008 | C11: 유월의보리 바지락칼국수 소스 | D11: 본사제조 | E11: 20835 | F11: 7810 | G11: 5KG[PAK]
A12: Y | B12: A0009 | C12: 유월의보리 잡채 소스 | D12: 본사제조 | E12: 56200 | F12: 26083 | G12: 5KG[PAK]
A13: Y | B13: A0010 | C13: 유월의보리 양념간장 소스 | D13: 본사제조 | E13: 36300 | F13: 15032 | G13: 5KG[PAK]
A14: Y | B14: A0012 | C14: 유월의보리 유자연근장아찌 | D14: 본사제조 | E14: 43200 | F14: 17850 | G14: 5KG[PAK]
A15: Y | B15: A0013 | C15: 유월의보리 비빔 무생채 | D15: 본사제조 | E15: 31900 | F15: 7300 | G15: 5KG[PAK]
... A45: Y | B45: A0046 | C45: 유월의보리 닭정육 | D45: 본사제조 | E45: 25200 | F45: 12600 | G45: 2KG[PAK]

Sheet README
A1: 유월의보리 물류 원가 MASTER 사용법
A2: 1 | B2: PRODUCT_MASTER 시트의 제조원가(입력) F열만 채우면 됩니다.
A3: 2 | B3: 이카운트/ERP 판매현황 엑셀은 품목코드 포함 양식으로 다운로드합니다.
A4: 3 | B4: REPORT_TEMPLATE 시트에는 ERP 데이터를 A:I에 붙여넣으면 J:M이 자동 계산됩니다.
A5: 4 | B5: Railway 자동화에서는 PRODUCT_MASTER의 품목코드→제조원가를 읽어 SKU별 공급가-원가를 계산합니다.
A6: 주의 | B6: 품목코드는 절대 중간에 바꾸지 마세요. 신규 품목은 PRODUCT_MASTER에 먼저 추가하세요.
A7: 생성일 | B7: 2026-05-27

Sheet REPORT_TEMPLATE
A1: 일자-No. | B1: 품목코드 | C1: 품목명(규격) | D1: 수량 | E1: 단가 | F1: 공급가액 | G1: 부가세 | H1: 합계 | I1: 거래처명 | J1: 제조원가(단위) | K1: 총제조원가 | L1: 물류이익 | M1: 마진율 | O1: 월말 리포트 집계식 예시
J2: =IFERROR(_xludf.XLOOKUP(B2,PRODUCT_MASTER!C2,PRODUCT_MASTER!C6),"") | K2: =IFERROR(D2*J2,"") | L2: =IFERROR(F2-K2,"") | M2: =IFERROR(L2/F2,"") | O2: 항목 | P2: 수식/설명
J3: =IFERROR(_xludf.XLOOKUP(B3,PRODUCT_MASTER!C2,PRODUCT_MASTER!C6),"") | K3: =IFERROR(D3*J3,"") | L3: =IFERROR(F3-K3,"") | M3: =IFERROR(L3/F3,"") | O3: 매장별 본사공급액 | P3: =SUMIFS(공급가액, 거래처명, 매장명)
J4: =IFERROR(_xludf.XLOOKUP(B4,PRODUCT_MASTER!C2,PRODUCT_MASTER!C6),"") | K4: =IFERROR(D4*J4,"") | L4: =IFERROR(F4-K4,"") | M4: =IFERROR(L4/F4,"") | O4: SKU별 공급액 | P4: =SUMIFS(공급가액, 품목코드, 코드)
J5: =IFERROR(_xludf.XLOOKUP(B5,PRODUCT_MASTER!C2,PRODUCT_MASTER!C6),"") | K5: =IFERROR(D5*J5,"") | L5: =IFERROR(F5-K5,"") | M5: =IFERROR(L5/F5,"") | O5: SKU별 제조원가 | P5: =SUMIFS(총제조원가, 품목코드, 코드)
J6: =IFERROR(_xludf.XLOOKUP(B6,PRODUCT_MASTER!C2,PRODUCT_MASTER!C6),"") | K6: =IFERROR(D6*J6,"") | L6: =IFERROR(F6-K6,"") | M6: =IFERROR(L6/F6,"") | O6: SKU별 이익 | P6: =공급액-제조원가
J7: =IFERROR(_xludf.XLOOKUP(B7,PRODUCT_MASTER!C2,PRODUCT_MASTER!C6),"") | K7: =IFERROR(D7*J7,"") | L7: =IFERROR(F7-K7,"") | M7: =IFERROR(L7/F7,"") | O7: SKU별 마진율 | P7: =이익/공급액
J8: =IFERROR(_xludf.XLOOKUP(B8,PRODUCT_MASTER!C2,PRODUCT_MASTER!C6),"") | K8: =IFERROR(D8*J8,"") | L8: =IFERROR(F8-K8,"") | M8: =IFERROR(L8/F8,"") | O8: 총매출 대비 공급비율 | P8: =본사공급액/POS월매출
J9: =IFERROR(_xludf.XLOOKUP(B9,PRODUCT_MASTER!C2,PRODUCT_MASTER!C6),"") | K9: =IFERROR(D9*J9,"") | L9: =IFERROR(F9-K9,"") | M9: =IFERROR(L9/F9,"")
J10: =IFERROR(_xludf.XLOOKUP(B10,PRODUCT_MASTER!C2,PRODUCT_MASTER!C6),"") | K10: =IFERROR(D10*J10,"") | L10: =IFERROR(F10-K10,"") | M10: =IFERROR(L10/F10,"")
J11: =IFERROR(_xludf.XLOOKUP(B11,PRODUCT_MASTER!C2,PRODUCT_MASTER!C6),"") | K11: =IFERROR(D11*J11,"") | L11: =IFERROR(F11-K11,"") | M11: =IFERROR(L11/F11,"")
J12: =IFERROR(_xludf.XLOOKUP(B12,PRODUCT_MASTER!C2,PRODUCT_MASTER!C6),"") | K12: =IFERROR(D12*J12,"") | L12: =IFERROR(F12-K12,"") | M12: =IFERROR(L12/F12,"")
J13: =IFERROR(_xludf.XLOOKUP(B13,PRODUCT_MASTER!C2,PRODUCT_MASTER!C6),"") | K13: =IFERROR(D13*J13,"") | L13: =IFERROR(F13-K13,"") | M13: =IFERROR(L13/F13,"")
J14: =IFERROR(_xludf.XLOOKUP(B14,PRODUCT_MASTER!C2,PRODUCT_MASTER!C6),"") | K14: =IFERROR(D14*J14,"") | L14: =IFERROR(F14-K14,"") | M14: =IFERROR(L14/F14,"")
J15: =IFERROR(_xludf.XLOOKUP(B15,PRODUCT_MASTER!C2,PRODUCT_MASTER!C6),"") | K15: =IFERROR(D15*J15,"") | L15: =IFERROR(F15-K15,"") | M15: =IFERROR(L15/F15,"")
J16: =IFERROR(_xludf.XLOOKUP(B16,PRODUCT_MASTER!C2,PRODUCT_MASTER!C6),"") | K16: =IFERROR(D16*J16,"") | L16: =IFERROR(F16-K16,"") | M16: =IFERROR(L16/F16,"")
J17: =IFERROR(_xludf.XLOOKUP(B17,PRODUCT_MASTER!C2,PRODUCT_MASTER!C6),"") | K17: =IFERROR(D17*J17,"") | L17: =IFERROR(F17-K17,"") | M17: =IFERROR(L17/F17,"")
J18: =IFERROR(_xludf.XLOOKUP(B18,PRODUCT_MASTER!C2,PRODUCT_MASTER!C6),"") | K18: =IFERROR(D18*J18,"") | L18: =IFERROR(F18-K18,"") | M18: =IFERROR(L18/F18,"")
J19: =IFERROR(_xludf.XLOOKUP(B19,PRODUCT_MASTER!C2,PRODUCT_MASTER!C6),"") | K19: =IFERROR(D19*J19,"") | L19: =IFERROR(F19-K19,"") | M19: =IFERROR(L19/F19,"")
J20: =IFERROR(_xludf.XLOOKUP(B20,PRODUCT_MASTER!C2,PRODUCT_MASTER!C6),"") | K20: =IFERROR(D20*J20,"") | L20: =IFERROR(F20-K20,"") | M20: =IFERROR(L20/F20,"")
J21: =IFERROR(_xludf.XLOOKUP(B21,PRODUCT_MASTER!C2,PRODUCT_MASTER!C6),"") | K21: =IFERROR(D21*J21,"") | L21: =IFERROR(F21-K21,"") | M21: =IFERROR(L21/F21,"")
J22: =IFERROR(_xludf.XLOOKUP(B22,PRODUCT_MASTER!C2,PRODUCT_MASTER!C6),"") | K22: =IFERROR(D22*J22,"") | L22: =IFERROR(F22-K22,"") | M22: =IFERROR(L22/F22,"")
J23: =IFERROR(_xludf.XLOOKUP(B23,PRODUCT_MASTER!C2,PRODUCT_MASTER!C6),"") | K23: =IFERROR(D23*J23,"") | L23: =IFERROR(F23-K23,"") | M23: =IFERROR(L23/F23,"")
J24: =IFERROR(_xludf.XLOOKUP(B24,PRODUCT_MASTER!C2,PRODUCT_MASTER!C6),"") | K24: =IFERROR(D24*J24,"") | L24: =IFERROR(F24-K24,"") | M24: =IFERROR(L24/F24,"")
J25: =IFERROR(_xludf.XLOOKUP(B25,PRODUCT_MASTER!C2,PRODUCT_MASTER!C6),"") | K25: =IFERROR(D25*J25,"") | L25: =IFERROR(F25-K25,"") | M25: =IFERROR(L25/F25,"")
J26: =IFERROR(_xludf.XLOOKUP(B26,PRODUCT_MASTER!C2,PRODUCT_MASTER!C6),"") | K26: =IFERROR(D26*J26,"") | L26: =IFERROR(F26-K26,"") | M26: =IFERROR(L26/F26,"")
J27: =IFERROR(_xludf.XLOOKUP(B27,PRODUCT_MASTER!C2,PRODUCT_MASTER!C6),"") | K27: =IFERROR(D27*J27,"") | L27: =IFERROR(F27-K27,"") | M27: =IFERROR(L27/F27,"")
J28: =IFERROR(_xludf.XLOOKUP(B28,PRODUCT_MASTER!C2,PRODUCT_MASTER!C6),"") | K28: =IFERROR(D28*J28,"") | L28: =IFERROR(F28-K28,"") | M28: =IFERROR(L28/F28,"")
J29: =IFERROR(_xludf.XLOOKUP(B29,PRODUCT_MASTER!C2,PRODUCT_MASTER!C6),"") | K29: =IFERROR(D29*J29,"") | L29: =IFERROR(F29-K29,"") | M29: =IFERROR(L29/F29,"")
J30: =IFERROR(_xludf.XLOOKUP(B30,PRODUCT_MASTER!C2,PRODUCT_MASTER!C6),"") | K30: =IFERROR(D30*J30,"") | L30: =IFERROR(F30-K30,"") | M30: =IFERROR(L30/F30,"")
J31: =IFERROR(_xludf.XLOOKUP(B31,PRODUCT_MASTER!C2,PRODUCT_MASTER!C6),"") | K31: =IFERROR(D31*J31,"") | L31: =IFERROR(F31-K31,"") | M31: =IFERROR(L31/F31,"")
J32: =IFERROR(_xludf.XLOOKUP(B32,PRODUCT_MASTER!C2,PRODUCT_MASTER!C6),"") | K32: =IFERROR(D32*J32,"") | L32: =IFERROR(F32-K32,"") | M32: =IFERROR(L32/F32,"")
J33: =IFERROR(_xludf.XLOOKUP(B33,PRODUCT_MASTER!C2,PRODUCT_MASTER!C6),"") | K33: =IFERROR(D33*J33,"") | L33: =IFERROR(F33-K33,"") | M33: =IFERROR(L33/F33,"")
J34: =IFERROR(_xludf.XLOOKUP(B34,PRODUCT_MASTER!C2,PRODUCT_MASTER!C6),"") | K34: =IFERROR(D34*J34,"") | L34: =IFERROR(F34-K34,"") | M34: =IFERROR(L34/F34,"")
J35: =IFERROR(_xludf.XLOOKUP(B35,PRODUCT_MASTER!C2,PRODUCT_MASTER!C6),"") | K35: =IFERROR(D35*J35,"") | L35: =IFERROR(F35-K35,"") | M35: =IFERROR(L35/F35,"")
J36: =IFERROR(_xludf.XLOOKUP(B36,PRODUCT_MASTER!C2,PRODUCT_MASTER!C6),"") | K36: =IFERROR(D36*J36,"") | L36: =IFERROR(F36-K36,"") | M36: =IFERROR(L36/F36,"")
J37: =IFERROR(_xludf.XLOOKUP(B37,PRODUCT_MASTER!C2,PRODUCT_MASTER!C6),"") | K37: =IFERROR(D37*J37,"") | L37: =IFERROR(F37-K37,"") | M37: =IFERROR(L37/F37,"")
J38: =IFERROR(_xludf.XLOOKUP(B38,PRODUCT_MASTER!C2,PRODUCT_MASTER!C6),"") | K38: =IFERROR(D38*J38,"") | L38: =IFERROR(F38-K38,"") | M38: =IFERROR(L38/F38,"")
J39: =IFERROR(_xludf.XLOOKUP(B39,PRODUCT_MASTER!C2,PRODUCT_MASTER!C6),"") | K39: =IFERROR(D39*J39,"") | L39: =IFERROR(F39-K39,"") | M39: =IFERROR(L39/F39,"")
J40: =IFERROR(_xludf.XLOOKUP(B40,PRODUCT_MASTER!C2,PRODUCT_MASTER!C6),"") | K40: =IFERROR(D40*J40,"") | L40: =IFERROR(F40-K40,"") | M40: =IFERROR(L40/F40,"")
...
